{
  "bad": false,
  "new_version": "3.46.0.7",
  "new_version_attempts": {
    "3.30.0.5": 1,
    "3.30.0.6": 1,
    "3.30.0.7": 1,
    "3.30.1.1": 1,
    "3.30.1.2": 1,
    "3.30.1.3": 1,
    "3.32.0.2": 1,
    "3.32.0.3": 1,
    "3.32.0.4": 1,
    "3.32.0.5": 1,
    "3.32.1.1": 1,
    "3.32.1.2": 1,
    "3.32.1.3": 1,
    "3.32.1.4": 1,
    "3.32.1.5": 1,
    "3.32.1.6": 1,
    "3.32.1.7": 1,
    "3.34.0.1": 1,
    "3.35.0.2": 1,
    "3.36.0.1": 1,
    "3.36.0.2": 1,
    "3.36.0.3": 1,
    "3.36.0.4": 1,
    "3.36.1.1": 1,
    "3.36.1.2": 1,
    "3.36.1.3": 1,
    "3.36.1.4": 1,
    "3.36.1.5": 1,
    "3.38.0.1": 1,
    "3.38.0.2": 1,
    "3.38.0.3": 1,
    "3.38.0.4": 2,
    "3.40.0.1": 6,
    "3.40.0.2": 1,
    "3.40.0.3": 1,
    "3.40.0.4": 1,
    "3.42.0.1": 1,
    "3.42.0.2": 1,
    "3.42.0.3": 1,
    "3.42.0.4": 1,
    "3.44.0.1": 1,
    "3.44.0.2": 1,
    "3.44.0.3": 1,
    "3.46.0.1": 14,
    "3.46.0.2": 1,
    "3.46.0.7": 494
  },
  "new_version_errors": {
    "3.40.0.1": "The recipe did not change in the version migration, a URL did not hash, or there is jinja2 syntax the bot cannot handle!\n\nPlease check the URLs in your recipe with version '3.40.0.1' to make sure they exist!\n\nWe also found the following errors:\n\n - could not hash URL template 'https://pypi.io/packages/source/{{ name[0] }}/{{ name }}/{{ name }}-{{ version }}.tar.gz'\n",
    "3.46.0.1": "The recipe did not change in the version migration, a URL did not hash, or there is jinja2 syntax the bot cannot handle!\n\nPlease check the URLs in your recipe with version '3.46.0.1' to make sure they exist!\n\nWe also found the following errors:\n\n - could not hash URL template 'https://pypi.io/packages/source/{{ name[0] }}/{{ name }}/{{ name }}-{{ version }}.tar.gz'\n",
    "3.46.0.7": "bot error (<a href=\"https://github.com/regro/cf-scripts/actions/runs/16888982699\">bot CI job</a>): main:\nTraceback (most recent call last):\n  File \"/opt/autotick-bot/conda_forge_tick/container_cli.py\", line 119, in _run_bot_task\n    data = func(attrs=attrs, **kwargs)\n           ^^^^^^^^^^^^^^^^^^^^^^^^^^^\n  File \"/opt/autotick-bot/conda_forge_tick/container_cli.py\", line 231, in _migrate_feedstock\n    data = run_migration_local(\n           ^^^^^^^^^^^^^^^^^^^^\n  File \"/opt/autotick-bot/conda_forge_tick/migration_runner.py\", line 269, in run_migration_local\n    data[\"migrate_return_value\"] = migrator.migrate(\n                                   ^^^^^^^^^^^^^^^^^\n  File \"/opt/autotick-bot/conda_forge_tick/migrators/version.py\", line 291, in migrate\n    version = attrs.get(\"version_pr_info\", {}).get(\"new_version\", None)\n              ^^^^^^^^^^^^^^^^^^^^^^^^^^^^^^^^^^^^^^^^^^^^^^^^^^^^^^^^^\n  File \"<frozen _collections_abc>\", line 774, in get\n  File \"/opt/autotick-bot/conda_forge_tick/lazy_json_backends.py\", line 1049, in __getitem__\n    self._load()\n  File \"/opt/autotick-bot/conda_forge_tick/lazy_json_backends.py\", line 1007, in _load\n    data_str = backend.hget(self.hashmap, self.node)\n               ^^^^^^^^^^^^^^^^^^^^^^^^^^^^^^^^^^^^^\n  File \"/opt/autotick-bot/conda_forge_tick/lazy_json_backends.py\", line 292, in hget\n    r.raise_for_status()\n  File \"/opt/conda/envs/cf-scripts/lib/python3.11/site-packages/requests/models.py\", line 1026, in raise_for_status\n    raise HTTPError(http_error_msg, response=self)\nrequests.exceptions.HTTPError: 503 Server Error: Service Unavailable for url: https://github.com/regro/cf-graph-countyfair/raw/master/version_pr_info/3/8/d/8/8/h2o-py.json\n"
  }
}