{
  "PRed": [
    {
      "PR": {
        "number": 1,
        "state": "closed"
      },
      "data": {
        "bot_rerun": false,
        "migrator_name": "MigrationYaml",
        "migrator_object_version": 1,
        "migrator_version": 0,
        "name": "python311"
      },
      "keys": [
        "bot_rerun",
        "migrator_name",
        "migrator_object_version",
        "migrator_version",
        "name"
      ]
    },
    {
      "PR": {
        "labels": [],
        "number": 2,
        "state": "closed"
      },
      "data": {
        "bot_rerun": false,
        "migrator_name": "MigrationYaml",
        "migrator_object_version": 1,
        "migrator_version": 0,
        "name": "python312"
      },
      "keys": [
        "bot_rerun",
        "migrator_name",
        "migrator_object_version",
        "migrator_version",
        "name"
      ]
    },
    {
      "PR": {
        "__lazy_json__": "pr_json/2143186752.json"
      },
      "data": {
        "bot_rerun": false,
        "migrator_name": "MigrationYaml",
        "migrator_object_version": 1,
        "migrator_version": 0,
        "name": "python313"
      },
      "keys": [
        "bot_rerun",
        "migrator_name",
        "migrator_object_version",
        "migrator_version",
        "name"
      ]
    }
  ],
  "bad": false,
  "pinning_version": "2024.10.24.08.31.46",
  "pre_pr_migrator_attempts": {
    "pypy38": 6
  },
  "pre_pr_migrator_status": {
    "pypy38": "bot error (<a href=\"https://github.com/regro/autotick-bot/actions/runs/3954382363\">bot CI job</a>): main: Traceback (most recent call last):\n  File \"/home/runner/work/autotick-bot/autotick-bot/cf-scripts/conda_forge_tick/auto_tick.py\", line 1166, in _run_migrator\n    migrator_uid, pr_json = run(\n  File \"/home/runner/work/autotick-bot/autotick-bot/cf-scripts/conda_forge_tick/auto_tick.py\", line 279, in run\n    eval_cmd(\n  File \"/home/runner/work/autotick-bot/autotick-bot/cf-scripts/conda_forge_tick/utils.py\", line 340, in eval_cmd\n    c.check_returncode()\n  File \"/usr/share/miniconda3/envs/run_env/lib/python3.9/subprocess.py\", line 460, in check_returncode\n    raise CalledProcessError(self.returncode, self.args, self.stdout,\nsubprocess.CalledProcessError: Command 'conda smithy rerender -c auto --no-check-uptodate' returned non-zero exit status 1.\n"
  },
  "smithy_version": "3.43.0"
}